Workbook

Sheet Resumen
B2: UTILIZACION DE LA FLOTA
B3: =Reporte!B3 -> MAGNEX_COL
B5: =+data!A2 -> Fecha del reporte | C5: =data!B2 -> 46202
B6: =data!A5 -> Días | C6: =data!B5 -> 30 | AJ6: =CONCATENATE(PROPER($C$7), " Driven") -> Km Driven
B7: =data!A6 -> Unidad de distancia | C7: =data!B6 -> KM | AJ7: =CONCATENATE(PROPER($C$7)," per day (Avg.)") -> Km per day (Avg.)
B9: =CLEAN(+Reporte!O14) -> (1) DISTANCIA RECORRIDA | K9: =CLEAN(+Reporte!P14) -> (2) DIAS CONDUCIDOS
C11: =UPPER($C$7) -> KM | H11: Vehículos | I11: % | L11: DIAS | Q11: Vehículos | R11: %
B12: Q1 | C12: De | D12: =IF($C$6=90,VLOOKUP($B12,parámetros!$B$4:$D$8,2,FALSE()),0)+IF($C$6=60,VLOOKUP($B12,parámetros!$F$4:$H$8,2,FALSE()),0)+IF(OR($C$6=30,$C$6=31,$C$6=29,$C$6=28),VLOOKUP($B12,parámetros!$J$4:$L$8,2,FALSE()),0)+IF($C$6=7,VLOOKUP($B12,parámetros!$N$4:$P$8,2,FALSE()),0) -> 0 | E12: a | F12: =IF($C$6=90,VLOOKUP($B12,parámetros!$B$4:$D$8,3,FALSE()),0)+IF($C$6=60,VLOOKUP($B12,parámetros!$F$4:$H$8,3,FALSE()),0)+IF(OR($C$6=30,$C$6=31,$C$6=29,$C$6=28),VLOOKUP($B12,parámetros!$J$4:$L$8,3,FALSE()),0)+IF($C$6=7,VLOOKUP($B12,parámetros!$N$4:$P$8,3,FALSE()),0) -> 66.666667 | G12: =IF($C$6=90,VLOOKUP($B12,parámetros!$B$4:$E$8,4,FALSE()),IF($C$6=60,VLOOKUP($B12,parámetros!$F$4:$I$8,4,FALSE()),IF(OR($C$6=30,$C$6=31,$C$6=29,$C$6=28),VLOOKUP($B12,parámetros!$J$4:$M$8,4,FALSE()),IF($C$6=7,VLOOKUP($B12,parámetros!$N$4:$Q$8,4,FALSE()),0)))) -> Menos de 67 | H12: =SUMPRODUCT(SUBTOTAL(3,OFFSET(Reporte!O16:O222,ROW(Reporte!O16:O222)-MIN(ROW(Reporte!O16:O222)),0,1)),(Reporte!O16:O222>=D12)*(Reporte!O16:O222<D13)) -> #VALUE! | I12: =H12/$H$17 -> #VALUE! | K12: Q1 | L12: De | M12: =IF($C$6=90,VLOOKUP($K12,parámetros!$B$12:$D$16,2,FALSE()),0)+IF($C$6=60,VLOOKUP($K12,parámetros!$F$12:$H$16,2,FALSE()),0)+IF(OR($C$6=30,$C$6=31,$C$6=29,$C$6=28),VLOOKUP($K12,parámetros!$J$12:$L$16,2,FALSE()),0)+IF($C$6=7,VLOOKUP($K12,parámetros!$N$12:$P$16,2,FALSE()),0) -> 0 | N12: a | O12: =IF($C$6=90,VLOOKUP($K12,parámetros!$B$12:$D$16,3,FALSE()),0)+IF($C$6=60,VLOOKUP($K12,parámetros!$F$12:$H$16,3,FALSE()),0)+IF(OR($C$6=30,$C$6=31,$C$6=29,$C$6=28),VLOOKUP($K12,parámetros!$J$12:$L$16,3,FALSE()),0)+IF($C$6=7,VLOOKUP($K12,parámetros!$N$12:$P$16,3,FALSE()),0) -> 6 | P12: =IF($C$6=90,VLOOKUP($K12,parámetros!$B$12:$E$16,4,FALSE()),IF($C$6=60,VLOOKUP($K12,parámetros!$F$12:$I$16,4,FALSE()),IF(OR($C$6=30,$C$6=31,$C$6=29,$C$6=28),VLOOKUP($K12,parámetros!$J$12:$M$16,4,FALSE()),IF($C$6=7,VLOOKUP($K12,parámetros!$N$12:$Q$16,4,FALSE()),0)))) -> Menos de 6 | Q12: =SUMPRODUCT(SUBTOTAL(3,OFFSET(Reporte!P16:P222,ROW(Reporte!P16:P222)-MIN(ROW(Reporte!P16:P222)),0,1)),(Reporte!P16:P222>=M12)*(Reporte!P16:P222<M13)) -> #VALUE! | R12: =Q12/$Q$17 -> #VALUE!
B13: Q2 | C13: De | D13: =IF($C$6=90,VLOOKUP($B13,parámetros!$B$4:$D$8,2,FALSE()),0)+IF($C$6=60,VLOOKUP($B13,parámetros!$F$4:$H$8,2,FALSE()),0)+IF(OR($C$6=30,$C$6=31,$C$6=29,$C$6=28),VLOOKUP($B13,parámetros!$J$4:$L$8,2,FALSE()),0)+IF($C$6=7,VLOOKUP($B13,parámetros!$N$4:$P$8,2,FALSE()),0) -> 66.666667 | E13: a | F13: =IF($C$6=90,VLOOKUP($B13,parámetros!$B$4:$D$8,3,FALSE()),0)+IF($C$6=60,VLOOKUP($B13,parámetros!$F$4:$H$8,3,FALSE()),0)+IF(OR($C$6=30,$C$6=31,$C$6=29,$C$6=28),VLOOKUP($B13,parámetros!$J$4:$L$8,3,FALSE()),0)+IF($C$6=7,VLOOKUP($B13,parámetros!$N$4:$P$8,3,FALSE()),0) -> 166.66667 | G13: =IF($C$6=90,VLOOKUP($B13,parámetros!$B$4:$E$8,4,FALSE()),IF($C$6=60,VLOOKUP($B13,parámetros!$F$4:$I$8,4,FALSE()),IF(OR($C$6=30,$C$6=31,$C$6=29,$C$6=28),VLOOKUP($B13,parámetros!$J$4:$M$8,4,FALSE()),IF($C$6=7,VLOOKUP($B13,parámetros!$N$4:$Q$8,4,FALSE()),0)))) -> 67 a 167 | H13: =SUMPRODUCT(SUBTOTAL(3,OFFSET(Reporte!O16:O222,ROW(Reporte!O16:O222)-MIN(ROW(Reporte!O16:O222)),0,1)),(Reporte!O16:O222>=D13)*(Reporte!O16:O222<D14)) -> #VALUE! | I13: =H13/$H$17 -> #VALUE! | K13: Q2 | L13: De | M13: =IF($C$6=90,VLOOKUP($K13,parámetros!$B$12:$D$16,2,FALSE()),0)+IF($C$6=60,VLOOKUP($K13,parámetros!$F$12:$H$16,2,FALSE()),0)+IF(OR($C$6=30,$C$6=31,$C$6=29,$C$6=28),VLOOKUP($K13,parámetros!$J$12:$L$16,2,FALSE()),0)+IF($C$6=7,VLOOKUP($K13,parámetros!$N$12:$P$16,2,FALSE()),0) -> 6 | N13: a | O13: =IF($C$6=90,VLOOKUP($K13,parámetros!$B$12:$D$16,3,FALSE()),0)+IF($C$6=60,VLOOKUP($K13,parámetros!$F$12:$H$16,3,FALSE()),0)+IF(OR($C$6=30,$C$6=31,$C$6=29,$C$6=28),VLOOKUP($K13,parámetros!$J$12:$L$16,3,FALSE()),0)+IF($C$6=7,VLOOKUP($K13,parámetros!$N$12:$P$16,3,FALSE()),0) -> 12 | P13: =IF($C$6=90,VLOOKUP($K13,parámetros!$B$12:$E$16,4,FALSE()),IF($C$6=60,VLOOKUP($K13,parámetros!$F$12:$I$16,4,FALSE()),IF(OR($C$6=30,$C$6=31,$C$6=29,$C$6=28),VLOOKUP($K13,parámetros!$J$12:$M$16,4,FALSE()),IF($C$6=7,VLOOKUP($K13,parámetros!$N$12:$Q$16,4,FALSE()),0)))) -> 6 a 12 | Q13: =SUMPRODUCT(SUBTOTAL(3,OFFSET(Reporte!P16:P222,ROW(Reporte!P16:P222)-MIN(ROW(Reporte!P16:P222)),0,1)),(Reporte!P16:P222>=M13)*(Reporte!P16:P222<M14)) -> #VALUE! | R13: =Q13/$Q$17 -> #VALUE!
B14: Q3 | C14: De | D14: =IF($C$6=90,VLOOKUP($B14,parámetros!$B$4:$D$8,2,FALSE()),0)+IF($C$6=60,VLOOKUP($B14,parámetros!$F$4:$H$8,2,FALSE()),0)+IF(OR($C$6=30,$C$6=31,$C$6=29,$C$6=28),VLOOKUP($B14,parámetros!$J$4:$L$8,2,FALSE()),0)+IF($C$6=7,VLOOKUP($B14,parámetros!$N$4:$P$8,2,FALSE()),0) -> 166.66667 | E14: a | F14: =IF($C$6=90,VLOOKUP($B14,parámetros!$B$4:$D$8,3,FALSE()),0)+IF($C$6=60,VLOOKUP($B14,parámetros!$F$4:$H$8,3,FALSE()),0)+IF(OR($C$6=30,$C$6=31,$C$6=29,$C$6=28),VLOOKUP($B14,parámetros!$J$4:$L$8,3,FALSE()),0)+IF($C$6=7,VLOOKUP($B14,parámetros!$N$4:$P$8,3,FALSE()),0) -> 500 | G14: =IF($C$6=90,VLOOKUP($B14,parámetros!$B$4:$E$8,4,FALSE()),IF($C$6=60,VLOOKUP($B14,parámetros!$F$4:$I$8,4,FALSE()),IF(OR($C$6=30,$C$6=31,$C$6=29,$C$6=28),VLOOKUP($B14,parámetros!$J$4:$M$8,4,FALSE()),IF($C$6=7,VLOOKUP($B14,parámetros!$N$4:$Q$8,4,FALSE()),0)))) -> 167 a 500 | H14: =SUMPRODUCT(SUBTOTAL(3,OFFSET(Reporte!O16:O222,ROW(Reporte!O16:O222)-MIN(ROW(Reporte!O16:O222)),0,1)),(Reporte!O16:O222>=D14)*(Reporte!O16:O222<D15)) -> #VALUE! | I14: =H14/$H$17 -> #VALUE! | K14: Q3 | L14: De | M14: =IF($C$6=90,VLOOKUP($K14,parámetros!$B$12:$D$16,2,FALSE()),0)+IF($C$6=60,VLOOKUP($K14,parámetros!$F$12:$H$16,2,FALSE()),0)+IF(OR($C$6=30,$C$6=31,$C$6=29,$C$6=28),VLOOKUP($K14,parámetros!$J$12:$L$16,2,FALSE()),0)+IF($C$6=7,VLOOKUP($K14,parámetros!$N$12:$P$16,2,FALSE()),0) -> 12 | N14: a | O14: =IF($C$6=90,VLOOKUP($K14,parámetros!$B$12:$D$16,3,FALSE()),0)+IF($C$6=60,VLOOKUP($K14,parámetros!$F$12:$H$16,3,FALSE()),0)+IF(OR($C$6=30,$C$6=31,$C$6=29,$C$6=28),VLOOKUP($K14,parámetros!$J$12:$L$16,3,FALSE()),0)+IF($C$6=7,VLOOKUP($K14,parámetros!$N$12:$P$16,3,FALSE()),0) -> 18 | P14: =IF($C$6=90,VLOOKUP($K14,parámetros!$B$12:$E$16,4,FALSE()),IF($C$6=60,VLOOKUP($K14,parámetros!$F$12:$I$16,4,FALSE()),IF(OR($C$6=30,$C$6=31,$C$6=29,$C$6=28),VLOOKUP($K14,parámetros!$J$12:$M$16,4,FALSE()),IF($C$6=7,VLOOKUP($K14,parámetros!$N$12:$Q$16,4,FALSE()),0)))) -> 12 a 18 | Q14: =SUMPRODUCT(SUBTOTAL(3,OFFSET(Reporte!P16:P222,ROW(Reporte!P16:P222)-MIN(ROW(Reporte!P16:P222)),0,1)),(Reporte!P16:P222>=M14)*(Reporte!P16:P222<M15)) -> #VALUE! | R14: =Q14/$Q$17 -> #VALUE!
B15: Q4 | C15: De | D15: =IF($C$6=90,VLOOKUP($B15,parámetros!$B$4:$D$8,2,FALSE()),0)+IF($C$6=60,VLOOKUP($B15,parámetros!$F$4:$H$8,2,FALSE()),0)+IF(OR($C$6=30,$C$6=31,$C$6=29,$C$6=28),VLOOKUP($B15,parámetros!$J$4:$L$8,2,FALSE()),0)+IF($C$6=7,VLOOKUP($B15,parámetros!$N$4:$P$8,2,FALSE()),0) -> 500 | E15: a | F15: =IF($C$6=90,VLOOKUP($B15,parámetros!$B$4:$D$8,3,FALSE()),0)+IF($C$6=60,VLOOKUP($B15,parámetros!$F$4:$H$8,3,FALSE()),0)+IF(OR($C$6=30,$C$6=31,$C$6=29,$C$6=28),VLOOKUP($B15,parámetros!$J$4:$L$8,3,FALSE()),0)+IF($C$6=7,VLOOKUP($B15,parámetros!$N$4:$P$8,3,FALSE()),0) -> 1000 | G15: =IF($C$6=90,VLOOKUP($B15,parámetros!$B$4:$E$8,4,FALSE()),IF($C$6=60,VLOOKUP($B15,parámetros!$F$4:$I$8,4,FALSE()),IF(OR($C$6=30,$C$6=31,$C$6=29,$C$6=28),VLOOKUP($B15,parámetros!$J$4:$M$8,4,FALSE()),IF($C$6=7,VLOOKUP($B15,parámetros!$N$4:$Q$8,4,FALSE()),0)))) -> 500 a 1,000 | H15: =SUMPRODUCT(SUBTOTAL(3,OFFSET(Reporte!O16:O222,ROW(Reporte!O16:O222)-MIN(ROW(Reporte!O16:O222)),0,1)),(Reporte!O16:O222>=D15)*(Reporte!O16:O222<D16)) -> #VALUE! | I15: =H15/$H$17 -> #VALUE! | K15: Q4 | L15: De | M15: =IF($C$6=90,VLOOKUP($K15,parámetros!$B$12:$D$16,2,FALSE()),0)+IF($C$6=60,VLOOKUP($K15,parámetros!$F$12:$H$16,2,FALSE()),0)+IF(OR($C$6=30,$C$6=31,$C$6=29,$C$6=28),VLOOKUP($K15,parámetros!$J$12:$L$16,2,FALSE()),0)+IF($C$6=7,VLOOKUP($K15,parámetros!$N$12:$P$16,2,FALSE()),0) -> 18 | N15: a | O15: =IF($C$6=90,VLOOKUP($K15,parámetros!$B$12:$D$16,3,FALSE()),0)+IF($C$6=60,VLOOKUP($K15,parámetros!$F$12:$H$16,3,FALSE()),0)+IF(OR($C$6=30,$C$6=31,$C$6=29,$C$6=28),VLOOKUP($K15,parámetros!$J$12:$L$16,3,FALSE()),0)+IF($C$6=7,VLOOKUP($K15,parámetros!$N$12:$P$16,3,FALSE()),0) -> 24 | P15: =IF($C$6=90,VLOOKUP($K15,parámetros!$B$12:$E$16,4,FALSE()),IF($C$6=60,VLOOKUP($K15,parámetros!$F$12:$I$16,4,FALSE()),IF(OR($C$6=30,$C$6=31,$C$6=29,$C$6=28),VLOOKUP($K15,parámetros!$J$12:$M$16,4,FALSE()),IF($C$6=7,VLOOKUP($K15,parámetros!$N$12:$Q$16,4,FALSE()),0)))) -> 18 a 24 | Q15: =SUMPRODUCT(SUBTOTAL(3,OFFSET(Reporte!P16:P222,ROW(Reporte!P16:P222)-MIN(ROW(Reporte!P16:P222)),0,1)),(Reporte!P16:P222>=M15)*(Reporte!P16:P222<M16)) -> #VALUE! | R15: =Q15/$Q$17 -> #VALUE!
B16: Q5 | C16: Más de | D16: =IF($C$6=90,VLOOKUP($B16,parámetros!$B$4:$D$8,2,FALSE()),0)+IF($C$6=60,VLOOKUP($B16,parámetros!$F$4:$H$8,2,FALSE()),0)+IF(OR($C$6=30,$C$6=31,$C$6=29,$C$6=28),VLOOKUP($B16,parámetros!$J$4:$L$8,2,FALSE()),0)+IF($C$6=7,VLOOKUP($B16,parámetros!$N$4:$P$8,2,FALSE()),0) -> 1000 | F16: =IF($C$6=90,VLOOKUP($B16,parámetros!$B$4:$D$8,3,FALSE()),0)+IF($C$6=60,VLOOKUP($B16,parámetros!$F$4:$H$8,3,FALSE()),0)+IF(OR($C$6=30,$C$6=31,$C$6=29,$C$6=28),VLOOKUP($B16,parámetros!$J$4:$L$8,3,FALSE()),0)+IF($C$6=7,VLOOKUP($B16,parámetros!$N$4:$P$8,3,FALSE()),0) -> 0 | G16: =IF($C$6=90,VLOOKUP($B16,parámetros!$B$4:$E$8,4,FALSE()),IF($C$6=60,VLOOKUP($B16,parámetros!$F$4:$I$8,4,FALSE()),IF(OR($C$6=30,$C$6=31,$C$6=29,$C$6=28),VLOOKUP($B16,parámetros!$J$4:$M$8,4,FALSE()),IF($C$6=7,VLOOKUP($B16,parámetros!$N$4:$Q$8,4,FALSE()),0)))) -> Más de 1,000 | H16: =SUMPRODUCT((SUBTOTAL(103,OFFSET(Reporte!O16:O222,ROW(Reporte!O16:O222)-MIN(ROW(Reporte!O16:O222)),0,1)))*(Reporte!O16:O222>=D16)) -> 27 | I16: =H16/$H$17 -> #VALUE! | K16: Q5 | L16: De | M16: =IF($C$6=90,VLOOKUP($K16,parámetros!$B$12:$D$16,2,FALSE()),0)+IF($C$6=60,VLOOKUP($K16,parámetros!$F$12:$H$16,2,FALSE()),0)+IF(OR($C$6=30,$C$6=31,$C$6=29,$C$6=28),VLOOKUP($K16,parámetros!$J$12:$L$16,2,FALSE()),0)+IF($C$6=7,VLOOKUP($K16,parámetros!$N$12:$P$16,2,FALSE()),0) -> 24 | N16: a | O16: =IF($C$6=90,VLOOKUP($K16,parámetros!$B$12:$D$16,3,FALSE()),0)+IF($C$6=60,VLOOKUP($K16,parámetros!$F$12:$H$16,3,FALSE()),0)+IF(OR($C$6=30,$C$6=31,$C$6=29,$C$6=28),VLOOKUP($K16,parámetros!$J$12:$L$16,3,FALSE()),0)+IF($C$6=7,VLOOKUP($K16,parámetros!$N$12:$P$16,3,FALSE()),0) -> 30 | P16: =IF($C$6=90,VLOOKUP($K16,parámetros!$B$12:$E$16,4,FALSE()),IF($C$6=60,VLOOKUP($K16,parámetros!$F$12:$I$16,4,FALSE()),IF(OR($C$6=30,$C$6=31,$C$6=29,$C$6=28),VLOOKUP($K16,parámetros!$J$12:$M$16,4,FALSE()),IF($C$6=7,VLOOKUP($K16,parámetros!$N$12:$Q$16,4,FALSE()),0)))) -> 24 a 30 | Q16: =SUMPRODUCT(SUBTOTAL(103,OFFSET(Reporte!P16:P222,ROW(Reporte!P16:P222)-MIN(ROW(Reporte!P16:P222)),0,1))*(Reporte!P16:P222>=M16)) -> 17 | R16: =Q16/$Q$17 -> #VALUE!
H17: =SUM(H12:H16) -> #VALUE! | Q17: =SUM(Q12:Q16) -> #VALUE!
B18: Uso promedio | C18: =AVERAGE(Reporte!O16:O222) -> 680.07246 | D18: =C7 -> KM | K18: Uso promedio | L18: =AVERAGE(Reporte!P16:P222) -> 8.8067633 | M18: Días
B47: =CLEAN(+Reporte!AC15) -> (3) HORAS DE USO POR DIA | K47: =CLEAN(+Reporte!AD15) -> (4) KM CONDUCIDOS POR DIA
C49: HORAS | H49: Vehículos | I49: % | L49: =UPPER($C$7) -> KM | Q49: Vehículos | R49: %
B50: Q1 | C50: De | D50: 0 | E50: a | F50: 2 | G50: Menos de 2 | H50: =SUMPRODUCT(SUBTOTAL(3,OFFSET(Reporte!AC16:AC222,ROW(Reporte!AC16:AC222)-MIN(ROW(Reporte!AC16:AC222)),0,1)),(Reporte!AC16:AC222>=D50)*(Reporte!AC16:AC222<D51)) -> #VALUE! | I50: =H50/$H$55 -> #VALUE! | K50: Q1 | L50: De | M50: 0 | N50: a | O50: 25 | P50: Menos de 25 | Q50: =SUMPRODUCT(SUBTOTAL(3,OFFSET(Reporte!AD16:AD222,ROW(Reporte!AD16:AD222)-MIN(ROW(Reporte!AD16:AD222)),0,1)),(Reporte!AD16:AD222>=M50)*(Reporte!AD16:AD222<M51)) -> #VALUE! | R50: =Q50/$Q$55 -> #VALUE!
B51: Q2 | C51: De | D51: 2 | E51: a | F51: 4 | G51: 2 a 4 | H51: =SUMPRODUCT(SUBTOTAL(3,OFFSET(Reporte!AC16:AC222,ROW(Reporte!AC16:AC222)-MIN(ROW(Reporte!AC16:AC222)),0,1)),(Reporte!AC16:AC222>=D51)*(Reporte!AC16:AC222<D52)) -> #VALUE! | I51: =H51/$H$55 -> #VALUE! | K51: Q2 | L51: De | M51: 25 | N51: a | O51: 50 | P51: 25 a 50 | Q51: =SUMPRODUCT(SUBTOTAL(3,OFFSET(Reporte!AD16:AD222,ROW(Reporte!AD16:AD222)-MIN(ROW(Reporte!AD16:AD222)),0,1)),(Reporte!AD16:AD222>=M51)*(Reporte!AD16:AD222<M52)) -> #VALUE! | R51: =Q51/$Q$55 -> #VALUE!
B52: Q3 | C52: De | D52: 4 | E52: a | F52: 6 | G52: 4 a 6 | H52: =SUMPRODUCT(SUBTOTAL(3,OFFSET(Reporte!AC16:AC222,ROW(Reporte!AC16:AC222)-MIN(ROW(Reporte!AC16:AC222)),0,1)),(Reporte!AC16:AC222>=D52)*(Reporte!AC16:AC222<D53)) -> #VALUE! | I52: =H52/$H$55 -> #VALUE! | K52: Q3 | L52: De | M52: 50 | N52: a | O52: 100 | P52: 50 a 100 | Q52: =SUMPRODUCT(SUBTOTAL(3,OFFSET(Reporte!AD16:AD222,ROW(Reporte!AD16:AD222)-MIN(ROW(Reporte!AD16:AD222)),0,1)),(Reporte!AD16:AD222>=M52)*(Reporte!AD16:AD222<M53)) -> #VALUE! | R52: =Q52/$Q$55 -> #VALUE!
B53: Q4 | C53: De | D53: 6 | E53: a | F53: 8 | G53: 6 a 8 | H53: =SUMPRODUCT(SUBTOTAL(3,OFFSET(Reporte!AC16:AC222,ROW(Reporte!AC16:AC222)-MIN(ROW(Reporte!AC16:AC222)),0,1)),(Reporte!AC16:AC222>=D53)*(Reporte!AC16:AC222<D54)) -> #VALUE! | I53: =H53/$H$55 -> #VALUE! | K53: Q4 | L53: De | M53: 100 | N53: a | O53: 150 | P53: 100 a 150 | Q53: =SUMPRODUCT(SUBTOTAL(3,OFFSET(Reporte!AD16:AD222,ROW(Reporte!AD16:AD222)-MIN(ROW(Reporte!AD16:AD222)),0,1)),(Reporte!AD16:AD222>=M53)*(Reporte!AD16:AD222<M54)) -> #VALUE! | R53: =Q53/$Q$55 -> #VALUE!
B54: Q5 | C54: Más de | D54: 8 | G54: Más de 8 | H54: =SUMPRODUCT((SUBTOTAL(103,OFFSET(Reporte!AC16:AC222,ROW(Reporte!AC16:AC222)-MIN(ROW(Reporte!AC16:AC222)),0,1)))*(Reporte!AC16:AC222>D54)) -> 46 | I54: =H54/$H$55 -> #VALUE! | K54: Q5 | L54: Más de | M54: 150 | P54: Más de 150 | Q54: =COUNT(_xlfn._xlws.FILTER(Reporte!AD16:AD222,(Reporte!AD16:AD222 > M54)*(SUBTOTAL(103,OFFSET(Reporte!AD16:AD222,ROW(Reporte!AD16:AD222)-MIN(ROW(Reporte!AD16:AD222)),0,1))))) -> 16 | R54: =Q54/$Q$55 -> #VALUE!
H55: =SUM(H50:H54) -> #VALUE! | Q55: =SUM(Q50:Q54) -> #VALUE!
B56: Uso promedio | C56: =AVERAGE(Reporte!AC16:AC222) -> 5.0819391 | D56: Horas/día | K56: Uso promedio | L56: =AVERAGE(Reporte!AD16:AD222) -> 69.719228 | M56: =CONCATENATE(PROPER($C$7),"/día") -> Km/día
H86: TIEMPO PROM. DE CONDUCCION VS. TIEMPO EN RALENTI
I88: Categorías | J88: Horas | K88: %
I89: Tiempo de Conducción | J89: =Reporte!T12 -> 1.3479497 | K89: =J89/$J$91 -> 0.67405568
I90: Tiempo en Ralentí | J90: =Reporte!Y12 -> 0.65181048 | K90: =J90/$J$91 -> 0.32594432
J91: =SUM(J89:J90) -> 1.9997602
C122: =+B9 -> (1) DISTANCIA RECORRIDA | H122: =CONCATENATE("Muestra la apertura de ",LOWER(C7)," conducidos por su flota dentro del período de tiempo especificado.") -> Muestra la apertura de km conducidos por su flota dentro del período de tiempo especificado.
C123: =+K9 -> (2) DIAS CONDUCIDOS | H123: Representa el número de días conducidos por su flota dentro del período de tiempo especificado.
C124: =+B47 -> (3) HORAS DE USO POR DIA | H124: Basado en una jornada laboral promedio de 8 horas, indica el número promedio de horas por día que los vehículos fueron utilizados
C125: =+K47 -> (4) KM CONDUCIDOS POR DIA | H125: =CONCATENATE("Representa el promedio de ",LOWER($C$7)," recorridos por día por los vehículos.") -> Representa el promedio de km recorridos por día por los vehículos.
C126: =+H86 -> TIEMPO PROM. DE CONDUCCION VS. TIEMPO EN RALENTI | H126: Representa el tiempo promedio en que los vehículos fueron utilizados en comparación con el tiempo que estuvieron en ralentí.

Sheet Reporte
B2: UTILIZACION DE LA FLOTA
B3: =+data!B1 -> MAGNEX_COL
B5: =data!A2 -> Fecha del reporte | C5: =data!B2 -> 46202 | AE5: (*) | AF5: Ingrese manualmente el valor deseado para su región en las celdas marcadas en amarillo
B6: =data!A3 -> Desde | C6: =data!B3 -> 46173
B7: =data!A4 -> Hasta | C7: =data!B4 -> 46202 | AE7: JORNADA LABORAL (*) | AH7: Costo promedio del combustible $ (*) | AI7: Consumo promedio de combustible en ralentí por hora
B8: =data!A5 -> Días | C8: =data!B5 -> 30 | AE8: 8 | AF8: HORAS | AH8: 3.5 | AI8: =+IFERROR(VLOOKUP(C9,parámetros!$C$21:$E$22,2,FALSE()),"") -> 1 | AJ8: =+IFERROR(VLOOKUP(C9,parámetros!$C$21:$E$22,3,FALSE()),"") -> Litros | AK8: =+IFERROR(VLOOKUP(E9,parámetros!$C$21:$E$22,2,FALSE()),"")
B9: Unidad de Distancia | C9: =data!B6 -> KM
N10: Odómetro Promedio | O10: PROM. DE DISTANCIA RECORRIDA | P10: PROM. DE DIAS CONDUCIDOS | Q10: TIEMPO PROMEDIO DE CONDUCCION | V10: TIEMPO PROMEDIO EN RALENTI | AA10: Prom. total de tiempo conducido + Ralentí (días) | AC10: UTILIZACION | AJ10: Tabla de referencia rápida
B11: Nota: Tenga en cuenta que sus vehículos solo se mostrarán en el reporte si están asignados a un solo grupo en Geotab. | Q11: Horas | R11: Minutos | S11: Segundos | T11: PROM. TOTAL DE TIEMPO CONDUCIDO (Días) | U11: =+U15 -> % CONDUCIDO | V11: Horas | W11: Minutos | X11: Segundos | Y11: PROM. TOTAL DE TIEMPO EN RALENTI (Días) | Z11: =+Z15 -> % EN RALENTI | AC11: PROM. DE HORAS DE USO POR DIA | AD11: =UPPER(CONCATENATE("PROM.DE ",$C$9," CONDUCIDOS POR DIA")) -> PROM.DE KM CONDUCIDOS POR DIA | AE11: =UPPER(CONCATENATE("VELOCIDAD PROM. (",$C$9," por hora)","")) -> VELOCIDAD PROM. (KM POR HORA) | AF11: PROM. USO DE JORNADA LABORAL(%) | AG11: PROM. DE DIAS CONDUCIDOS (%) | AH11: COSTO TOTAL DE COMBUSTIBLE EN RALENTI | AJ11: 1 Milla | AK11: = | AL11: 1.6 Kilómetros
N12: =SUBTOTAL(1,N$16:N$222) -> 56168.444 | O12: =SUBTOTAL(1,O$16:O$222) -> 680.07246 | P12: =SUBTOTAL(1,P$16:P$222) -> 8.8067633 | Q12: =SUBTOTAL(1,Q$16:Q$222) -> 31.855072 | R12: =SUBTOTAL(1,R$16:R$222) -> 29.285024 | S12: =SUBTOTAL(1,S$16:S$222) -> 27.492754 | T12: =SUBTOTAL(1,T$16:T$222)/24 -> 1.3479497 | U12: =SUBTOTAL(1,U$16:U$222) -> 0.64937327 | V12: =SUBTOTAL(1,V$16:V$222) -> 15.164251 | W12: =SUBTOTAL(1,W$16:W$222) -> 28.309179 | X12: =SUBTOTAL(1,X$16:X$222) -> 26.570048 | Y12: =SUBTOTAL(1,Y$16:Y$222)/24 -> 0.65181048 | Z12: =SUBTOTAL(1,Z$16:Z$222) -> 0.33613397 | AA12: =+T12+Y12 -> 1.9997602 | AC12: =SUBTOTAL(1,AC$16:AC$222) -> 5.0819391 | AD12: =SUBTOTAL(1,AD$16:AD$222) -> 69.719228 | AE12: =SUBTOTAL(1,AE$16:AE$222) -> 20.078848 | AF12: =SUBTOTAL(1,AF$16:AF$222) -> 0.63524239 | AG12: =SUBTOTAL(1,AG$16:AG$222) -> 0.29355878 | AH12: =SUBTOTAL(9,AH$16:AH$222) -> 11333.681 | AJ12: 1 Galón | AK12: = | AL12: 3.78541 Litros
AJ13: 1 USD | AK13: = | AL13: 1.42 CAD
B14: Grupo1 | C14: Grupo2 | D14: Grupo3 | E14: Grupo4 | F14: Grupo5 | G14: Grupo6 | H14: Grupo7 | I14: Grupo8 | J14: Vehículo | K14: Conductor | L14: GPS | M14: Cámara | N14: Odómetro | O14: (1) DISTANCIA RECORRIDA | P14: (2) DIAS CONDUCIDOS | Q14: TIEMPO CONDUCIDO | V14: TIEMPO EN RALENTI | AA14: Tiempo total conducido + Ralentí (horas) | AC14: UTILIZACION | AJ14: 1 USD | AK14: = | AL14: 0.95 EUR
Q15: Horas | R15: Minutos | S15: Segundos | T15: TIEMPO NETO CONDUCIDO (Horas) | U15: % CONDUCIDO | V15: Horas | W15: Minutos | X15: Segundos | Y15: TIEMPO NETO EN RALENTI (Horas) | Z15: % EN RALENTI | AC15: (3) HORAS DE USO POR DIA | AD15: =UPPER(CONCATENATE("(4) ",$C$9," CONDUCIDOS POR DIA")) -> (4) KM CONDUCIDOS POR DIA | AE15: =+AE11 -> VELOCIDAD PROM. (KM POR HORA) | AF15: USO DE JORNADA LABORAL (%) | AG15: DIAS CONDUCIDOS (%) | AH15: COSTO DE COMBUSTIBLE EN RALENTI
B16: Magnex | C16: Zona Generación | D16: ECP 1107 Rubiales Serv. Integrales | J16: QLO286 | L16: ✔️ | M16: =data!J8 -> 30 | N16: 30820 | O16: 6044 | P16: 30 | Q16: 324 | R16: 19 | S16: 25 | T16: =+((Q16)+(R16/60)+(S16/3600)) -> 324.32361 | U16: =IFERROR(T16/$AA16,0) -> 0.82928245 | V16: 66 | W16: 45 | X16: 57 | Y16: =+((V16)+(W16/60)+(X16/3600)) -> 66.765833 | Z16: =+IFERROR(Y16/$AA16,0) -> 0.17071755 | AA16: =+Y16+T16 -> 391.08944 | AC16: =+IFERROR((AA16/P16),0) -> 13.036315 | AD16: =+IFERROR($O16/$P16,0) -> 201.46667 | AE16: =+IFERROR(O16/T16,0) -> 18.635708 | AF16: =+IFERROR(AA16/(P16*$AE$8),0) -> 1.6295394 | AG16: =+P16/$C$8 -> 1 | AH16: =+Y16*($AI$8*$AH$8) -> 233.68042
B17: Magnex | C17: Zona Centro | D17: GMA CENTRO | J17: NPY686 | L17: ✔️ | M17: =data!J8 -> 30 | N17: 24050 | O17: 1208 | P17: 22 | Q17: 42 | R17: 3 | S17: 4 | T17: =+((Q17)+(R17/60)+(S17/3600)) -> 42.051111 | U17: =IFERROR(T17/$AA17,0) -> 0.87050327 | V17: 6 | W17: 15 | X17: 20 | Y17: =+((V17)+(W17/60)+(X17/3600)) -> 6.2555556 | Z17: =+IFERROR(Y17/$AA17,0) -> 0.12949673 | AA17: =+Y17+T17 -> 48.306667 | AC17: =+IFERROR((AA17/P17),0) -> 2.1957576 | AD17: =+IFERROR($O17/$P17,0) -> 54.909091 | AE17: =+IFERROR(O17/T17,0) -> 28.726946 | AF17: =+IFERROR(AA17/(P17*$AE$8),0) -> 0.2744697 | AG17: =+P17/$C$8 -> 0.73333333 | AH17: =+Y17*($AI$8*$AH$8) -> 21.894444
B18: Magnex | C18: Zona Energy | D18: ENEL 6053 Zona III OPEX SOT SOC-GA | J18: PMV840 | L18: ✔️ | M18: =data!J8 -> 30 | N18: 7510 | O18: 483 | P18: 20 | Q18: 37 | R18: 13 | S18: 50 | T18: =+((Q18)+(R18/60)+(S18/3600)) -> 37.230556 | U18: =IFERROR(T18/$AA18,0) -> 0.69840029 | V18: 16 | W18: 4 | X18: 40 | Y18: =+((V18)+(W18/60)+(X18/3600)) -> 16.077778 | Z18: =+IFERROR(Y18/$AA18,0) -> 0.30159971 | AA18: =+Y18+T18 -> 53.308333 | AC18: =+IFERROR((AA18/P18),0) -> 2.6654167 | AD18: =+IFERROR($O18/$P18,0) -> 24.15 | AE18: =+IFERROR(O18/T18,0) -> 12.973215 | AF18: =+IFERROR(AA18/(P18*$AE$8),0) -> 0.33317708 | AG18: =+P18/$C$8 -> 0.66666667 | AH18: =+Y18*($AI$8*$AH$8) -> 56.272222
B19: Magnex | C19: Zona Energy | D19: ENEL 6053 Zona III OPEX SOT SOC-GA | J19: NPY798 | L19: ✔️ | M19: =data!J8 -> 30 | N19: 10809 | O19: 860 | P19: 26 | Q19: 66 | R19: 33 | S19: 51 | T19: =+((Q19)+(R19/60)+(S19/3600)) -> 66.564167 | U19: =IFERROR(T19/$AA19,0) -> 0.71892391 | V19: 26 | W19: 1 | X19: 28 | Y19: =+((V19)+(W19/60)+(X19/3600)) -> 26.024444 | Z19: =+IFERROR(Y19/$AA19,0) -> 0.28107609 | AA19: =+Y19+T19 -> 92.588611 | AC19: =+IFERROR((AA19/P19),0) -> 3.5611004 | AD19: =+IFERROR($O19/$P19,0) -> 33.076923 | AE19: =+IFERROR(O19/T19,0) -> 12.919864 | AF19: =+IFERROR(AA19/(P19*$AE$8),0) -> 0.44513755 | AG19: =+P19/$C$8 -> 0.86666667 | AH19: =+Y19*($AI$8*$AH$8) -> 91.085556
B20: Magnex | C20: Zona Energy | D20: ENEL 6054 Zona V OPEX SOT SOC-GA | J20: GSO698 | L20: ✔️ | M20: =data!J8 -> 30 | N20: 138492 | O20: 3187 | P20: 24 | Q20: 131 | R20: 38 | S20: 31 | T20: =+((Q20)+(R20/60)+(S20/3600)) -> 131.64194 | U20: =IFERROR(T20/$AA20,0) -> 0.76999103 | V20: 39 | W20: 19 | X20: 25 | Y20: =+((V20)+(W20/60)+(X20/3600)) -> 39.323611 | Z20: =+IFERROR(Y20/$AA20,0) -> 0.23000897 | AA20: =+Y20+T20 -> 170.96556 | AC20: =+IFERROR((AA20/P20),0) -> 7.1235648 | AD20: =+IFERROR($O20/$P20,0) -> 132.79167 | AE20: =+IFERROR(O20/T20,0) -> 24.209609 | AF20: =+IFERROR(AA20/(P20*$AE$8),0) -> 0.8904456 | AG20: =+P20/$C$8 -> 0.8 | AH20: =+Y20*($AI$8*$AH$8) -> 137.63264
B21: Magnex | C21: Zona Energy | D21: ENEL 6054 Zona V OPEX SOT SOC-GA | J21: NPY979 | L21: ✔️ | M21: =data!J8 -> 30 | N21: 20833 | O21: 1701 | P21: 20 | Q21: 72 | R21: 58 | S21: 59 | T21: =+((Q21)+(R21/60)+(S21/3600)) -> 72.983056 | U21: =IFERROR(T21/$AA21,0) -> 0.72172915 | V21: 28 | W21: 8 | X21: 22 | Y21: =+((V21)+(W21/60)+(X21/3600)) -> 28.139444 | Z21: =+IFERROR(Y21/$AA21,0) -> 0.27827085 | AA21: =+Y21+T21 -> 101.1225 | AC21: =+IFERROR((AA21/P21),0) -> 5.056125 | AD21: =+IFERROR($O21/$P21,0) -> 85.05 | AE21: =+IFERROR(O21/T21,0) -> 23.30678 | AF21: =+IFERROR(AA21/(P21*$AE$8),0) -> 0.63201562 | AG21: =+P21/$C$8 -> 0.66666667 | AH21: =+Y21*($AI$8*$AH$8) -> 98.488056
B22: Magnex | C22: Zona Energy | D22: ENEL 6054 Zona V OPEX SOT SOC-GA | J22: NPY794 | L22: ✔️ | M22: =data!J8 -> 30 | N22: 21171 | O22: 1042 | P22: 22 | Q22: 57 | R22: 40 | S22: 3 | T22: =+((Q22)+(R22/60)+(S22/3600)) -> 57.6675 | U22: =IFERROR(T22/$AA22,0) -> 0.79426652 | V22: 14 | W22: 56 | X22: 14 | Y22: =+((V22)+(W22/60)+(X22/3600)) -> 14.937222 | Z22: =+IFERROR(Y22/$AA22,0) -> 0.20573348 | AA22: =+Y22+T22 -> 72.604722 | AC22: =+IFERROR((AA22/P22),0) -> 3.3002146 | AD22: =+IFERROR($O22/$P22,0) -> 47.363636 | AE22: =+IFERROR(O22/T22,0) -> 18.069103 | AF22: =+IFERROR(AA22/(P22*$AE$8),0) -> 0.41252683 | AG22: =+P22/$C$8 -> 0.73333333 | AH22: =+Y22*($AI$8*$AH$8) -> 52.280278
B23: Magnex | C23: Zona Energy | D23: ENEL 6054 Zona V OPEX SOT SOC-GA | J23: NPY609 | L23: ✔️ | M23: =data!J8 -> 30 | N23: 18011 | O23: 1337 | P23: 22 | Q23: 68 | R23: 47 | S23: 36 | T23: =+((Q23)+(R23/60)+(S23/3600)) -> 68.793333 | U23: =IFERROR(T23/$AA23,0) -> 0.67766668 | V23: 32 | W23: 43 | X23: 18 | Y23: =+((V23)+(W23/60)+(X23/3600)) -> 32.721667 | Z23: =+IFERROR(Y23/$AA23,0) -> 0.32233332 | AA23: =+Y23+T23 -> 101.515 | AC23: =+IFERROR((AA23/P23),0) -> 4.6143182 | AD23: =+IFERROR($O23/$P23,0) -> 60.772727 | AE23: =+IFERROR(O23/T23,0) -> 19.435023 | AF23: =+IFERROR(AA23/(P23*$AE$8),0) -> 0.57678977 | AG23: =+P23/$C$8 -> 0.73333333 | AH23: =+Y23*($AI$8*$AH$8) -> 114.52583
B24: Magnex | C24: Zona Energy | D24: ENEL 6054 Zona V OPEX SOT SOC-GA | J24: NPY995 | L24: ✔️ | M24: =data!J8 -> 30 | N24: 18436 | O24: 1167 | P24: 21 | Q24: 56 | R24: 30 | S24: 46 | T24: =+((Q24)+(R24/60)+(S24/3600)) -> 56.512778 | U24: =IFERROR(T24/$AA24,0) -> 0.70863405 | V24: 23 | W24: 14 | X24: 10 | Y24: =+((V24)+(W24/60)+(X24/3600)) -> 23.236111 | Z24: =+IFERROR(Y24/$AA24,0) -> 0.29136595 | AA24: =+Y24+T24 -> 79.748889 | AC24: =+IFERROR((AA24/P24),0) -> 3.7975661 | AD24: =+IFERROR($O24/$P24,0) -> 55.571429 | AE24: =+IFERROR(O24/T24,0) -> 20.650197 | AF24: =+IFERROR(AA24/(P24*$AE$8),0) -> 0.47469577 | AG24: =+P24/$C$8 -> 0.7 | AH24: =+Y24*($AI$8*$AH$8) -> 81.326389
B25: Magnex | C25: Zona Energy | D25: ENEL 6054 Zona V OPEX SOT SOC-GA | J25: JSL414 | L25: ✔️ | M25: =data!J8 -> 30 | N25: 168484 | O25: 338 | P25: 9 | Q25: 14 | R25: 33 | S25: 52 | T25: =+((Q25)+(R25/60)+(S25/3600)) -> 14.564444 | U25: =IFERROR(T25/$AA25,0) -> 0.56339723 | V25: 11 | W25: 17 | X25: 12 | Y25: =+((V25)+(W25/60)+(X25/3600)) -> 11.286667 | Z25: =+IFERROR(Y25/$AA25,0) -> 0.43660277 | AA25: =+Y25+T25 -> 25.851111 | AC25: =+IFERROR((AA25/P25),0) -> 2.8723457 | AD25: =+IFERROR($O25/$P25,0) -> 37.555556 | AE25: =+IFERROR(O25/T25,0) -> 23.207202 | AF25: =+IFERROR(AA25/(P25*$AE$8),0) -> 0.35904321 | AG25: =+P25/$C$8 -> 0.3 | AH25: =+Y25*($AI$8*$AH$8) -> 39.503333
B26: Magnex | C26: Zona Energy | D26: ENEL 6054 Zona V OPEX SOT SOC-GA | J26: GSN681 | L26: ✔️ | M26: =data!J8 -> 30 | N26: 163678 | O26: 1858 | P26: 20 | Q26: 75 | R26: 50 | S26: 34 | T26: =+((Q26)+(R26/60)+(S26/3600)) -> 75.842778 | U26: =IFERROR(T26/$AA26,0) -> 0.7637507 | V26: 23 | W26: 27 | X26: 37 | Y26: =+((V26)+(W26/60)+(X26/3600)) -> 23.460278 | Z26: =+IFERROR(Y26/$AA26,0) -> 0.2362493 | AA26: =+Y26+T26 -> 99.303056 | AC26: =+IFERROR((AA26/P26),0) -> 4.9651528 | AD26: =+IFERROR($O26/$P26,0) -> 92.9 | AE26: =+IFERROR(O26/T26,0) -> 24.498048 | AF26: =+IFERROR(AA26/(P26*$AE$8),0) -> 0.6206441 | AG26: =+P26/$C$8 -> 0.66666667 | AH26: =+Y26*($AI$8*$AH$8) -> 82.110972
B27: Magnex | C27: Zona Energy | D27: ENEL 6054 Zona V OPEX SOT SOC-GA | J27: NPY976 | L27: ✔️ | M27: =data!J8 -> 30 | N27: 21065 | O27: 653 | P27: 19 | Q27: 34 | R27: 1 | S27: 42 | T27: =+((Q27)+(R27/60)+(S27/3600)) -> 34.028333 | U27: =IFERROR(T27/$AA27,0) -> 0.74717754 | V27: 11 | W27: 30 | X27: 51 | Y27: =+((V27)+(W27/60)+(X27/3600)) -> 11.514167 | Z27: =+IFERROR(Y27/$AA27,0) -> 0.25282246 | AA27: =+Y27+T27 -> 45.5425 | AC27: =+IFERROR((AA27/P27),0) -> 2.3969737 | AD27: =+IFERROR($O27/$P27,0) -> 34.368421 | AE27: =+IFERROR(O27/T27,0) -> 19.189891 | AF27: =+IFERROR(AA27/(P27*$AE$8),0) -> 0.29962171 | AG27: =+P27/$C$8 -> 0.63333333 | AH27: =+Y27*($AI$8*$AH$8) -> 40.299583
B28: Magnex | C28: Zona Energy | D28: ENEL 6054 Zona V OPEX SOT SOC-GA | J28: NPY986 | L28: ✔️ | M28: =data!J8 -> 30 | N28: 15024 | O28: 712 | P28: 18 | Q28: 34 | R28: 11 | S28: 37 | T28: =+((Q28)+(R28/60)+(S28/3600)) -> 34.193611 | U28: =IFERROR(T28/$AA28,0) -> 0.68728958 | V28: 15 | W28: 33 | X28: 28 | Y28: =+((V28)+(W28/60)+(X28/3600)) -> 15.557778 | Z28: =+IFERROR(Y28/$AA28,0) -> 0.31271042 | AA28: =+Y28+T28 -> 49.751389 | AC28: =+IFERROR((AA28/P28),0) -> 2.763966 | AD28: =+IFERROR($O28/$P28,0) -> 39.555556 | AE28: =+IFERROR(O28/T28,0) -> 20.822603 | AF28: =+IFERROR(AA28/(P28*$AE$8),0) -> 0.34549576 | AG28: =+P28/$C$8 -> 0.6 | AH28: =+Y28*($AI$8*$AH$8) -> 54.452222
B29: Magnex | C29: Zona Energy | D29: ENEL 6054 Zona V OPEX SOT SOC-GA | J29: NPY990 | L29: ✔️ | M29: =data!J8 -> 30 | N29: 19495 | O29: 1399 | P29: 21 | Q29: 62 | R29: 49 | S29: 30 | T29: =+((Q29)+(R29/60)+(S29/3600)) -> 62.825 | U29: =IFERROR(T29/$AA29,0) -> 0.89299957 | V29: 7 | W29: 31 | X29: 40 | Y29: =+((V29)+(W29/60)+(X29/3600)) -> 7.5277778 | Z29: =+IFERROR(Y29/$AA29,0) -> 0.10700043 | AA29: =+Y29+T29 -> 70.352778 | AC29: =+IFERROR((AA29/P29),0) -> 3.3501323 | AD29: =+IFERROR($O29/$P29,0) -> 66.619048 | AE29: =+IFERROR(O29/T29,0) -> 22.268205 | AF29: =+IFERROR(AA29/(P29*$AE$8),0) -> 0.41876653 | AG29: =+P29/$C$8 -> 0.7 | AH29: =+Y29*($AI$8*$AH$8) -> 26.347222
B30: Magnex | C30: Zona Energy | D30: ENEL 6054 Zona V OPEX SOT SOC-GA | J30: LJQ948 | L30: ✔️ | M30: =data!J8 -> 30 | N30: 203210 | O30: 493 | P30: 16 | Q30: 25 | R30: 35 | S30: 39 | T30: =+((Q30)+(R30/60)+(S30/3600)) -> 25.594167 | U30: =IFERROR(T30/$AA30,0) -> 0.39540902 | V30: 39 | W30: 8 | X30: 3 | Y30: =+((V30)+(W30/60)+(X30/3600)) -> 39.134167 | Z30: =+IFERROR(Y30/$AA30,0) -> 0.60459098 | AA30: =+Y30+T30 -> 64.728333 | AC30: =+IFERROR((AA30/P30),0) -> 4.0455208 | AD30: =+IFERROR($O30/$P30,0) -> 30.8125 | AE30: =+IFERROR(O30/T30,0) -> 19.262202 | AF30: =+IFERROR(AA30/(P30*$AE$8),0) -> 0.5056901 | AG30: =+P30/$C$8 -> 0.53333333 | AH30: =+Y30*($AI$8*$AH$8) -> 136.96958
B31: Magnex | C31: Zona Energy | D31: ENEL 6054 Zona V OPEX SOT SOC-GA | J31: NFX476 | L31: ✔️ | M31: =data!J8 -> 30 | N31: 96440 | O31: 852 | P31: 15 | Q31: 38 | R31: 24 | S31: 2 | T31: =+((Q31)+(R31/60)+(S31/3600)) -> 38.400556 | U31: =IFERROR(T31/$AA31,0) -> 0.74077527 | V31: 13 | W31: 26 | X31: 16 | Y31: =+((V31)+(W31/60)+(X31/3600)) -> 13.437778 | Z31: =+IFERROR(Y31/$AA31,0) -> 0.25922473 | AA31: =+Y31+T31 -> 51.838333 | AC31: =+IFERROR((AA31/P31),0) -> 3.4558889 | AD31: =+IFERROR($O31/$P31,0) -> 56.8 | AE31: =+IFERROR(O31/T31,0) -> 22.187179 | AF31: =+IFERROR(AA31/(P31*$AE$8),0) -> 0.43198611 | AG31: =+P31/$C$8 -> 0.5 | AH31: =+Y31*($AI$8*$AH$8) -> 47.032222
B32: Magnex | C32: Zona Energy | D32: ENEL 6054 Zona V OPEX SOT SOC-GA | J32: NPY987 | L32: ✔️ | M32: =data!J8 -> 30 | N32: 13527 | O32: 661 | P32: 13 | Q32: 31 | R32: 26 | S32: 59 | T32: =+((Q32)+(R32/60)+(S32/3600)) -> 31.449722 | U32: =IFERROR(T32/$AA32,0) -> 0.55483463 | V32: 25 | W32: 14 | X32: 0 | Y32: =+((V32)+(W32/60)+(X32/3600)) -> 25.233333 | Z32: =+IFERROR(Y32/$AA32,0) -> 0.44516537 | AA32: =+Y32+T32 -> 56.683056 | AC32: =+IFERROR((AA32/P32),0) -> 4.360235 | AD32: =+IFERROR($O32/$P32,0) -> 50.846154 | AE32: =+IFERROR(O32/T32,0) -> 21.017674 | AF32: =+IFERROR(AA32/(P32*$AE$8),0) -> 0.54502938 | AG32: =+P32/$C$8 -> 0.43333333 | AH32: =+Y32*($AI$8*$AH$8) -> 88.316667
B33: Magnex | C33: Zona Energy | D33: ENEL 6054 Zona V OPEX SOT SOC-GA | J33: NPY628 | L33: ✔️ | M33: =data!J8 -> 30 | N33: 13083 | O33: 1046 | P33: 18 | Q33: 52 | R33: 27 | S33: 51 | T33: =+((Q33)+(R33/60)+(S33/3600)) -> 52.464167 | U33: =IFERROR(T33/$AA33,0) -> 0.45248317 | V33: 63 | W33: 28 | X33: 59 | Y33: =+((V33)+(W33/60)+(X33/3600)) -> 63.483056 | Z33: =+IFERROR(Y33/$AA33,0) -> 0.54751683 | AA33: =+Y33+T33 -> 115.94722 | AC33: =+IFERROR((AA33/P33),0) -> 6.4415123 | AD33: =+IFERROR($O33/$P33,0) -> 58.111111 | AE33: =+IFERROR(O33/T33,0) -> 19.937418 | AF33: =+IFERROR(AA33/(P33*$AE$8),0) -> 0.80518904 | AG33: =+P33/$C$8 -> 0.6 | AH33: =+Y33*($AI$8*$AH$8) -> 222.19069
B34: Magnex | C34: Zona Energy | D34: ENEL 6054 Zona V OPEX SOT SOC-GA | J34: NPY978 | L34: ✔️ | M34: =data!J8 -> 30 | N34: 17791 | O34: 858 | P34: 17 | Q34: 40 | R34: 39 | S34: 2 | T34: =+((Q34)+(R34/60)+(S34/3600)) -> 40.650556 | U34: =IFERROR(T34/$AA34,0) -> 0.67197789 | V34: 19 | W34: 50 | X34: 36 | Y34: =+((V34)+(W34/60)+(X34/3600)) -> 19.843333 | Z34: =+IFERROR(Y34/$AA34,0) -> 0.32802211 | AA34: =+Y34+T34 -> 60.493889 | AC34: =+IFERROR((AA34/P34),0) -> 3.5584641 | AD34: =+IFERROR($O34/$P34,0) -> 50.470588 | AE34: =+IFERROR(O34/T34,0) -> 21.106723 | AF34: =+IFERROR(AA34/(P34*$AE$8),0) -> 0.44480801 | AG34: =+P34/$C$8 -> 0.56666667 | AH34: =+Y34*($AI$8*$AH$8) -> 69.451667
B35: Magnex | C35: Zona Energy | D35: ENEL 6054 Zona V OPEX SOT SOC-GA | J35: JSL356 | L35: ✔️ | M35: =data!J8 -> 30 | N35: 178134 | O35: 565 | P35: 12 | Q35: 41 | R35: 3 | S35: 45 | T35: =+((Q35)+(R35/60)+(S35/3600)) -> 41.0625 | U35: =IFERROR(T35/$AA35,0) -> 0.49056535 | V35: 42 | W35: 38 | X35: 31 | Y35: =+((V35)+(W35/60)+(X35/3600)) -> 42.641944 | Z35: =+IFERROR(Y35/$AA35,0) -> 0.50943465 | AA35: =+Y35+T35 -> 83.704444 | AC35: =+IFERROR((AA35/P35),0) -> 6.9753704 | AD35: =+IFERROR($O35/$P35,0) -> 47.083333 | AE35: =+IFERROR(O35/T35,0) -> 13.759513 | AF35: =+IFERROR(AA35/(P35*$AE$8),0) -> 0.8719213 | AG35: =+P35/$C$8 -> 0.4 | AH35: =+Y35*($AI$8*$AH$8) -> 149.24681
B36: Magnex | C36: Zona Energy | D36: ENEL 6054 Zona V OPEX SOT SOC-GA | J36: NPZ118 | L36: ✔️ | M36: =data!J8 -> 30 | N36: 21418 | O36: 373 | P36: 13 | Q36: 17 | R36: 48 | S36: 43 | T36: =+((Q36)+(R36/60)+(S36/3600)) -> 17.811944 | U36: =IFERROR(T36/$AA36,0) -> 0.67945621 | V36: 8 | W36: 24 | X36: 11 | Y36: =+((V36)+(W36/60)+(X36/3600)) -> 8.4030556 | Z36: =+IFERROR(Y36/$AA36,0) -> 0.32054379 | AA36: =+Y36+T36 -> 26.215 | AC36: =+IFERROR((AA36/P36),0) -> 2.0165385 | AD36: =+IFERROR($O36/$P36,0) -> 28.692308 | AE36: =+IFERROR(O36/T36,0) -> 20.941004 | AF36: =+IFERROR(AA36/(P36*$AE$8),0) -> 0.25206731 | AG36: =+P36/$C$8 -> 0.43333333 | AH36: =+Y36*($AI$8*$AH$8) -> 29.410694
B37: Magnex | C37: Zona Energy | D37: ENEL 6054 Zona V OPEX SOT SOC-GA | J37: GEU353 | L37: ✔️ | M37: =data!J8 -> 30 | N37: 117720 | O37: 512 | P37: 14 | Q37: 25 | R37: 11 | S37: 37 | T37: =+((Q37)+(R37/60)+(S37/3600)) -> 25.193611 | U37: =IFERROR(T37/$AA37,0) -> 0.70589563 | V37: 10 | W37: 29 | X37: 48 | Y37: =+((V37)+(W37/60)+(X37/3600)) -> 10.496667 | Z37: =+IFERROR(Y37/$AA37,0) -> 0.29410437 | AA37: =+Y37+T37 -> 35.690278 | AC37: =+IFERROR((AA37/P37),0) -> 2.5493056 | AD37: =+IFERROR($O37/$P37,0) -> 36.571429 | AE37: =+IFERROR(O37/T37,0) -> 20.322613 | AF37: =+IFERROR(AA37/(P37*$AE$8),0) -> 0.31866319 | AG37: =+P37/$C$8 -> 0.46666667 | AH37: =+Y37*($AI$8*$AH$8) -> 36.738333
B38: Magnex | C38: Zona Energy | D38: ENEL 6054 Zona V OPEX SOT SOC-GA | J38: NPY988 | L38: ✔️ | M38: =data!J8 -> 30 | N38: 17532 | O38: 623 | P38: 14 | Q38: 30 | R38: 6 | S38: 28 | T38: =+((Q38)+(R38/60)+(S38/3600)) -> 30.107778 | U38: =IFERROR(T38/$AA38,0) -> 0.84871739 | V38: 5 | W38: 22 | X38: 0 | Y38: =+((V38)+(W38/60)+(X38/3600)) -> 5.3666667 | Z38: =+IFERROR(Y38/$AA38,0) -> 0.15128261 | AA38: =+Y38+T38 -> 35.474444 | AC38: =+IFERROR((AA38/P38),0) -> 2.5338889 | AD38: =+IFERROR($O38/$P38,0) -> 44.5 | AE38: =+IFERROR(O38/T38,0) -> 20.692328 | AF38: =+IFERROR(AA38/(P38*$AE$8),0) -> 0.31673611 | AG38: =+P38/$C$8 -> 0.46666667 | AH38: =+Y38*($AI$8*$AH$8) -> 18.783333
B39: Magnex | C39: Zona Energy | D39: ENEL 6054 Zona V OPEX SOT SOC-GA | J39: PMV835 | L39: ✔️ | M39: =data!J8 -> 30 | N39: 13136 | O39: 431 | P39: 14 | Q39: 20 | R39: 31 | S39: 47 | T39: =+((Q39)+(R39/60)+(S39/3600)) -> 20.529722 | U39: =IFERROR(T39/$AA39,0) -> 0.76790483 | V39: 6 | W39: 12 | X39: 18 | Y39: =+((V39)+(W39/60)+(X39/3600)) -> 6.205 | Z39: =+IFERROR(Y39/$AA39,0) -> 0.23209517 | AA39: =+Y39+T39 -> 26.734722 | AC39: =+IFERROR((AA39/P39),0) -> 1.909623 | AD39: =+IFERROR($O39/$P39,0) -> 30.785714 | AE39: =+IFERROR(O39/T39,0) -> 20.993952 | AF39: =+IFERROR(AA39/(P39*$AE$8),0) -> 0.23870288 | AG39: =+P39/$C$8 -> 0.46666667 | AH39: =+Y39*($AI$8*$AH$8) -> 21.7175
B40: Magnex | C40: Zona Energy | D40: ENEL 6054 Zona V OPEX SOT SOC-GA | J40: NPY973 | L40: ✔️ | M40: =data!J8 -> 30 | N40: 16314 | O40: 426 | P40: 10 | Q40: 26 | R40: 31 | S40: 6 | T40: =+((Q40)+(R40/60)+(S40/3600)) -> 26.518333 | U40: =IFERROR(T40/$AA40,0) -> 0.72405555 | V40: 10 | W40: 6 | X40: 23 | Y40: =+((V40)+(W40/60)+(X40/3600)) -> 10.106389 | Z40: =+IFERROR(Y40/$AA40,0) -> 0.27594445 | AA40: =+Y40+T40 -> 36.624722 | AC40: =+IFERROR((AA40/P40),0) -> 3.6624722 | AD40: =+IFERROR($O40/$P40,0) -> 42.6 | AE40: =+IFERROR(O40/T40,0) -> 16.064358 | AF40: =+IFERROR(AA40/(P40*$AE$8),0) -> 0.45780903 | AG40: =+P40/$C$8 -> 0.33333333 | AH40: =+Y40*($AI$8*$AH$8) -> 35.372361
B41: Magnex | C41: Zona Energy | D41: ENEL 6054 Zona V OPEX SOT SOC-GA | J41: NPY797 | L41: ✔️ | M41: =data!J8 -> 30 | N41: 24510 | O41: 727 | P41: 11 | Q41: 35 | R41: 58 | S41: 6 | T41: =+((Q41)+(R41/60)+(S41/3600)) -> 35.968333 | U41: =IFERROR(T41/$AA41,0) -> 0.65706254 | V41: 18 | W41: 46 | X41: 22 | Y41: =+((V41)+(W41/60)+(X41/3600)) -> 18.772778 | Z41: =+IFERROR(Y41/$AA41,0) -> 0.34293746 | AA41: =+Y41+T41 -> 54.741111 | AC41: =+IFERROR((AA41/P41),0) -> 4.9764646 | AD41: =+IFERROR($O41/$P41,0) -> 66.090909 | AE41: =+IFERROR(O41/T41,0) -> 20.212224 | AF41: =+IFERROR(AA41/(P41*$AE$8),0) -> 0.62205808 | AG41: =+P41/$C$8 -> 0.36666667 | AH41: =+Y41*($AI$8*$AH$8) -> 65.704722
B42: Magnex | C42: Zona Energy | D42: ENEL 6054 Zona V OPEX SOT SOC-GA | J42: WNN254 | L42: ✔️ | M42: =data!J8 -> 30 | N42: 76569 | O42: 529 | P42: 13 | Q42: 32 | R42: 26 | S42: 16 | T42: =+((Q42)+(R42/60)+(S42/3600)) -> 32.437778 | U42: =IFERROR(T42/$AA42,0) -> 0.39066494 | V42: 50 | W42: 35 | X42: 40 | Y42: =+((V42)+(W42/60)+(X42/3600)) -> 50.594444 | Z42: =+IFERROR(Y42/$AA42,0) -> 0.60933506 | AA42: =+Y42+T42 -> 83.032222 | AC42: =+IFERROR((AA42/P42),0) -> 6.387094 | AD42: =+IFERROR($O42/$P42,0) -> 40.692308 | AE42: =+IFERROR(O42/T42,0) -> 16.308146 | AF42: =+IFERROR(AA42/(P42*$AE$8),0) -> 0.79838675 | AG42: =+P42/$C$8 -> 0.43333333 | AH42: =+Y42*($AI$8*$AH$8) -> 177.08056
...

Sheet parámetros
B2: Distancia total recorrida
B3: 90 | C3: días | F3: 60 | G3: días | J3: 30 | K3: días | N3: 7 | O3: días
B4: Q1 | C4: 0 | D4: 200 | E4: Menos de 200 | F4: Q1 | G4: 0 | H4: =+$F$3*D4/$B$3 -> 133.33333 | I4: Menos de 133 | J4: Q1 | K4: 0 | L4: =+$J$3*H4/$F$3 -> 66.666667 | M4: Menos de 67 | N4: Q1 | O4: 0 | P4: =+$N$3*L4/$J$3 -> 15.555556 | Q4: Menos de 16
B5: Q2 | C5: =+D4 -> 200 | D5: 500 | E5: 200 a 500 | F5: Q2 | G5: =+H4 -> 133.33333 | H5: =+$F$3*D5/$B$3 -> 333.33333 | I5: 133 a 333 | J5: Q2 | K5: =+L4 -> 66.666667 | L5: =+$J$3*H5/$F$3 -> 166.66667 | M5: 67 a 167 | N5: Q2 | O5: =+P4 -> 15.555556 | P5: =+$N$3*L5/$J$3 -> 38.888889 | Q5: 16 a 39
B6: Q3 | C6: =+D5 -> 500 | D6: 1500 | E6: 500 a 1,500 | F6: Q3 | G6: =+H5 -> 333.33333 | H6: =+$F$3*D6/$B$3 -> 1000 | I6: 333 a 1,000 | J6: Q3 | K6: =+L5 -> 166.66667 | L6: =+$J$3*H6/$F$3 -> 500 | M6: 167 a 500 | N6: Q3 | O6: =+P5 -> 38.888889 | P6: =+$N$3*L6/$J$3 -> 116.66667 | Q6: 39 a 117
B7: Q4 | C7: =+D6 -> 1500 | D7: 3000 | E7: 1,500 a 3,000 | F7: Q4 | G7: =+H6 -> 1000 | H7: =+$F$3*D7/$B$3 -> 2000 | I7: 1,000 a 2,000 | J7: Q4 | K7: =+L6 -> 500 | L7: =+$J$3*H7/$F$3 -> 1000 | M7: 500 a 1,000 | N7: Q4 | O7: =+P6 -> 116.66667 | P7: =+$N$3*L7/$J$3 -> 233.33333 | Q7: 117 a 233
B8: Q5 | C8: =+D7 -> 3000 | E8: Más de 3,000 | F8: Q5 | G8: =+H7 -> 2000 | I8: Más de 2,000 | J8: Q5 | K8: =+L7 -> 1000 | M8: Más de 1,000 | N8: Q5 | O8: =+P7 -> 233.33333 | Q8: Más de 233
B10: Total de días conducidos
B11: 90 | C11: días | F11: 60 | G11: días | J11: 30 | K11: días | N11: 7 | O11: días
B12: Q1 | C12: 0 | D12: =+B11*0.2 -> 18 | E12: Menos de 18 | F12: Q1 | G12: 0 | H12: =+F11*0.2 -> 12 | I12: Menos de 12 | J12: Q1 | K12: 0 | L12: =+J11*0.2 -> 6 | M12: Menos de 6 | N12: Q1 | O12: 0 | P12: =+N11*0.2 -> 1.4 | Q12: Menos de 1
B13: Q2 | C13: =+D12 -> 18 | D13: =+B11*0.4 -> 36 | E13: 18 a 36 | F13: Q2 | G13: =+H12 -> 12 | H13: =+F11*0.4 -> 24 | I13: 12 a 24 | J13: Q2 | K13: =+L12 -> 6 | L13: =+J11*0.4 -> 12 | M13: 6 a 12 | N13: Q2 | O13: =+P12 -> 1.4 | P13: =+N11*0.4 -> 2.8 | Q13: 1 a 3
B14: Q3 | C14: =+D13 -> 36 | D14: =+B11*0.6 -> 54 | E14: 36 a 54 | F14: Q3 | G14: =+H13 -> 24 | H14: =+F11*0.6 -> 36 | I14: 24 a 36 | J14: Q3 | K14: =+L13 -> 12 | L14: =+J11*0.6 -> 18 | M14: 12 a 18 | N14: Q3 | O14: =+P13 -> 2.8 | P14: =+N11*0.6 -> 4.2 | Q14: 3 a 4
B15: Q4 | C15: =+D14 -> 54 | D15: =+B11*0.8 -> 72 | E15: 54 a 72 | F15: Q4 | G15: =+H14 -> 36 | H15: =+F11*0.8 -> 48 | I15: 36 a 48 | J15: Q4 | K15: =+L14 -> 18 | L15: =+J11*0.8 -> 24 | M15: 18 a 24 | N15: Q4 | O15: =+P14 -> 4.2 | P15: =+N11*0.8 -> 5.6 | Q15: 4 a 6
B16: Q5 | C16: =+D15 -> 72 | D16: =+B11 -> 90 | E16: 72 a 90 | F16: Q5 | G16: =+H15 -> 48 | H16: =+F11 -> 60 | I16: 48 a 60 | J16: Q5 | K16: =+L15 -> 24 | L16: =+J11 -> 30 | M16: 24 a 30 | N16: Q5 | O16: =+P15 -> 5.6 | P16: =+N11 -> 7 | Q16: 6 a 7
C21: Km | D21: =+D22*3.78541 -> 1 | E21: Litros
C22: Millas | D22: 0.26417218 | E22: Galones

Sheet Grupo 1
A1: Grupo | B1: Vehículos | C1: GPS sin conexión 5+ días | D1: Días conducidos (promedio) | E1: Kilómetros conducidos (promedio) | F1: Horas conducidas (promedio) | G1: Tiempo en ralentí (promedio) | H1: % de utilización (días conducidos)
A2: Magnex | B2: 209 | C2: 0 | D2: 9 | E2: 679 | F2: 32:19:22 | G2: 15:37:08 | H2: 27%

Sheet Grupo 2
A1: Grupo 1 | B1: Grupo | C1: Vehículos | D1: GPS sin conexión 5+ días | E1: Días conducidos (promedio) | F1: Kilómetros conducidos (promedio) | G1: Horas conducidas (promedio) | H1: Tiempo en ralentí (promedio) | I1: % de utilización (días conducidos)
A2: Magnex | B2: Asset Information | C2: 209 | D2: 0 | E2: 9 | F2: 679 | G2: 32:19:22 | H2: 15:37:08 | I2: 27%
A3: Magnex | B3: CALIBRATION SERVICES | C3: 0 | D3: 0 | E3: 0 | F3: 0 | G3: 0:00:00 | H3: 0:00:00 | I3: -
A4: Magnex | B4: Zona Centro | C4: 2 | D4: 0 | E4: 23 | F4: 2073 | G4: 54:05:01 | H4: 4:54:22 | I4: 75%
A5: Magnex | B5: Zona Cerrejón | C5: 50 | D5: 0 | E5: 4 | F5: 473 | G5: 16:47:56 | H5: 11:15:25 | I5: 13%
A6: Magnex | B6: Zona Drummond | C6: 48 | D6: 0 | E6: 4 | F6: 353 | G6: 14:17:26 | H6: 12:43:29 | I6: 11%
A7: Magnex | B7: Zona Energy | C7: 78 | D7: 0 | E7: 11 | F7: 486 | G7: 26:55:31 | H7: 15:27:22 | I7: 33%
A8: Magnex | B8: Zona Generación | C8: 17 | D8: 0 | E8: 25 | F8: 3162 | G8: 165:36:32 | H8: 48:53:50 | I8: 84%
A9: Magnex | B9: Zona Occidente | C9: 12 | D9: 0 | E9: 5 | F9: 367 | G9: 12:14:57 | H9: 1:29:27 | I9: 14%
A10: Magnex | B10: Zona Tabarca | C10: 0 | D10: 0 | E10: 0 | F10: 0 | G10: 0:00:00 | H10: 0:00:00 | I10: -

Sheet Grupo 3
A1: Grupo 1 | B1: Grupo 2 | C1: Grupo | D1: Vehículos | E1: GPS sin conexión 5+ días | F1: Días conducidos (promedio) | G1: Kilómetros conducidos (promedio) | H1: Horas conducidas (promedio) | I1: Tiempo en ralentí (promedio) | J1: % de utilización (días conducidos)
A2: Magnex | B2: Asset Information | C2: Asset Purpose | D2: 0 | E2: 0 | F2: 0 | G2: 0 | H2: 0:00:00 | I2: 0:00:00 | J2: -
A3: Magnex | B3: Asset Information | C3: Asset Type | D3: 209 | E3: 0 | F3: 9 | G3: 679 | H3: 32:19:22 | I3: 15:37:08 | J3: 27%
A4: Magnex | B4: Zona Centro | C4: Campos Menores RegCentral | D4: 0 | E4: 0 | F4: 0 | G4: 0 | H4: 0:00:00 | I4: 0:00:00 | J4: -
A5: Magnex | B5: Zona Occidente | C5: CEN 8596 Estac ANDINA - PREVEN-CORREC | D5: 8 | E5: 0 | F5: 4 | G5: 262 | H5: 9:13:01 | I5: 0:55:32 | J5: 13%
A6: Magnex | B6: Zona Occidente | C6: CEN 8596 Estac CAÑO LIMON - MOH | D6: 0 | E6: 0 | F6: 0 | G6: 0 | H6: 0:00:00 | I6: 0:00:00 | J6: -
A7: Magnex | B7: Zona Occidente | C7: CEN 8596 Estac CAÑO LIMON-PREVEN-CORREC | D7: 0 | E7: 0 | F7: 0 | G7: 0 | H7: 0:00:00 | I7: 0:00:00 | J7: -
A8: Magnex | B8: Zona Occidente | C8: CEN 8596 Estac LLANOS - PREVEN-CORREC | D8: 4 | E8: 0 | F8: 6 | G8: 579 | H8: 18:18:48 | I8: 2:37:19 | J8: 18%
A9: Magnex | B9: Zona Occidente | C9: CEN 8596 Estac SUR - PREVEN - CORREC | D9: 0 | E9: 0 | F9: 0 | G9: 0 | H9: 0:00:00 | I9: 0:00:00 | J9: -
A10: Magnex | B10: Zona Cerrejón | C10: CERREJON 0174 Bombas-GA | D10: 13 | E10: 0 | F10: 4 | G10: 489 | H10: 16:30:53 | I10: 11:57:48 | J10: 12%
A11: Magnex | B11: Zona Cerrejón | C11: CERREJON 2022 Cabinas-GA | D11: 22 | E11: 0 | F11: 5 | G11: 515 | H11: 18:25:31 | I11: 12:01:49 | J11: 15%
A12: Magnex | B12: Zona Cerrejón | C12: CERREJON 3534 Soldadura-GA | D12: 14 | E12: 0 | F12: 4 | G12: 390 | H12: 14:42:47 | I12: 9:57:17 | J12: 11%
A13: Magnex | B13: Zona Drummond | C13: DRUMMOND 1547 Liviano-GA | D13: 5 | E13: 0 | F13: 4 | G13: 427 | H13: 15:23:04 | I13: 8:25:17 | J13: 11%
... A35: Magnex | B35: Zona Centro | C35: TRANSVERSAL IND | D35: 0 | E35: 0 | F35: 0 | G35: 0 | H35: 0:00:00 | I35: 0:00:00 | J35: -

Sheet Grupo 4
A1: Grupo 1 | B1: Grupo 2 | C1: Grupo 3 | D1: Grupo | E1: Vehículos | F1: GPS sin conexión 5+ días | G1: Días conducidos (promedio) | H1: Kilómetros conducidos (promedio) | I1: Horas conducidas (promedio) | J1: Tiempo en ralentí (promedio) | K1: % de utilización (días conducidos)
A2: Magnex | B2: Asset Information | C2: Asset Type | D2: Container | E2: 0 | F2: 0 | G2: 0 | H2: 0 | I2: 0:00:00 | J2: 0:00:00 | K2: -
A3: Magnex | B3: Asset Information | C3: Powertrain and Fuel Type | D3: Electric or Plug-In Hybrid | E3: 0 | F3: 0 | G3: 0 | H3: 0 | I3: 0:00:00 | J3: 0:00:00 | K3: -
A4: Magnex | B4: Asset Information | C4: Asset Type | D4: Equipment | E4: 0 | F4: 0 | G4: 0 | H4: 0 | I4: 0:00:00 | J4: 0:00:00 | K4: -
A5: Magnex | B5: Asset Information | C5: Powertrain and Fuel Type | D5: Fuel Cell Electric Vehicle | E5: 0 | F5: 0 | G5: 0 | H5: 0 | I5: 0:00:00 | J5: 0:00:00 | K5: -
A6: Magnex | B6: Asset Information | C6: Powertrain and Fuel Type | D6: Internal Combustion Engine | E6: 202 | F6: 0 | G6: 9 | H6: 699 | I6: 33:18:52 | J6: 16:01:05 | K6: 27%
A7: Magnex | B7: Asset Information | C7: Powertrain and Fuel Type | D7: Manually Classified Powertrain | E7: 15 | F7: 0 | G7: 7 | H7: 717 | I7: 27:26:25 | J7: 9:57:29 | K7: 23%
A8: Magnex | B8: Asset Information | C8: Asset Type | D8: Trailer | E8: 0 | F8: 0 | G8: 0 | H8: 0 | I8: 0:00:00 | J8: 0:00:00 | K8: -
A9: Magnex | B9: Asset Information | C9: Asset Type | D9: Vehicle | E9: 209 | F9: 0 | G9: 9 | H9: 679 | I9: 32:19:22 | J9: 15:37:08 | K9: 27%

Sheet Grupo 5
A1: Grupo 1 | B1: Grupo 2 | C1: Grupo 3 | D1: Grupo 4 | E1: Grupo | F1: Vehículos | G1: GPS sin conexión 5+ días | H1: Días conducidos (promedio) | I1: Kilómetros conducidos (promedio) | J1: Horas conducidas (promedio) | K1: Tiempo en ralentí (promedio) | L1: % de utilización (días conducidos)
A2: Magnex | B2: Asset Information | C2: Powertrain and Fuel Type | D2: Electric or Plug-In Hybrid | E2: Battery Electric Vehicle | F2: 0 | G2: 0 | H2: 0 | I2: 0 | J2: 0:00:00 | K2: 0:00:00 | L2: -
A3: Magnex | B3: Asset Information | C3: Powertrain and Fuel Type | D3: Internal Combustion Engine | E3: Biodiesel | F3: 0 | G3: 0 | H3: 0 | I3: 0 | J3: 0:00:00 | K3: 0:00:00 | L3: -
A4: Magnex | B4: Asset Information | C4: Powertrain and Fuel Type | D4: Internal Combustion Engine | E4: Compressed Natural Gas | F4: 0 | G4: 0 | H4: 0 | I4: 0 | J4: 0:00:00 | K4: 0:00:00 | L4: -
A5: Magnex | B5: Asset Information | C5: Powertrain and Fuel Type | D5: Internal Combustion Engine | E5: Diesel | F5: 197 | G5: 0 | H5: 9 | I5: 711 | J5: 33:49:11 | K5: 16:20:04 | L5: 28%
A6: Magnex | B6: Asset Information | C6: Powertrain and Fuel Type | D6: Internal Combustion Engine | E6: Ethanol | F6: 0 | G6: 0 | H6: 0 | I6: 0 | J6: 0:00:00 | K6: 0:00:00 | L6: -
A7: Magnex | B7: Asset Information | C7: Powertrain and Fuel Type | D7: Internal Combustion Engine | E7: Gasoline or Petrol | F7: 5 | G7: 0 | H7: 6 | I7: 234 | J7: 13:24:45 | K7: 3:33:10 | L7: 18%
A8: Magnex | B8: Asset Information | C8: Powertrain and Fuel Type | D8: Internal Combustion Engine | E8: Other Fuel Type | F8: 0 | G8: 0 | H8: 0 | I8: 0 | J8: 0:00:00 | K8: 0:00:00 | L8: -
A9: Magnex | B9: Asset Information | C9: Powertrain and Fuel Type | D9: Electric or Plug-In Hybrid | E9: Plug-in Hybrid Electric Vehicle | F9: 0 | G9: 0 | H9: 0 | I9: 0 | J9: 0:00:00 | K9: 0:00:00 | L9: -
A10: Magnex | B10: Asset Information | C10: Powertrain and Fuel Type | D10: Internal Combustion Engine | E10: Propane or Liquified Petroleum Gas | F10: 0 | G10: 0 | H10: 0 | I10: 0 | J10: 0:00:00 | K10: 0:00:00 | L10: -

Sheet data
A1: Organización | B1: MAGNEX_COL
A2: Fecha del reporte | B2: =B4 -> 46202
A3: Desde | B3: 46173
A4: Hasta | B4: 46202
A5: Días | B5: =B4-B3+1 -> 30
A6: Unidad de distancia | B6: KM
A7: Grupo 1 | B7: Grupo 2 | C7: Grupo 3 | D7: Grupo 4 | E7: Grupo 5 | F7: Vehículo | G7: Conductor actual | H7: GPS | I7: Odómetro KM | J7: Días conducidos | K7: Kilómetros conducidos | L7: Horas conducidas | M7: Tiempo en ralentí | N7: % de utilización (días conducidos)
A8: Magnex | B8: Zona Generación | C8: ECP 1107 Rubiales Serv. Integrales | F8: QLO286 | H8: ✔️ | I8: 30820 | J8: 30 | K8: 6044 | L8: 324:19:25 | M8: 66:45:57 | N8: 100%
A9: Magnex | B9: Zona Centro | C9: GMA CENTRO | F9: NPY686 | H9: ✔️ | I9: 24050 | J9: 22 | K9: 1208 | L9: 42:03:04 | M9: 6:15:20 | N9: 73%
A10: Magnex | B10: Zona Energy | C10: ENEL 6053 Zona III OPEX SOT SOC-GA | F10: PMV840 | H10: ✔️ | I10: 7510 | J10: 20 | K10: 483 | L10: 37:13:50 | M10: 16:04:40 | N10: 63%
A11: Magnex | B11: Zona Energy | C11: ENEL 6053 Zona III OPEX SOT SOC-GA | F11: NPY798 | H11: ✔️ | I11: 10809 | J11: 26 | K11: 860 | L11: 66:33:51 | M11: 26:01:28 | N11: 83%
A12: Magnex | B12: Zona Energy | C12: ENEL 6054 Zona V OPEX SOT SOC-GA | F12: GSO698 | H12: ✔️ | I12: 138492 | J12: 24 | K12: 3187 | L12: 131:38:31 | M12: 39:19:25 | N12: 80%
A13: Magnex | B13: Zona Energy | C13: ENEL 6054 Zona V OPEX SOT SOC-GA | F13: NPY979 | H13: ✔️ | I13: 20833 | J13: 20 | K13: 1701 | L13: 72:58:59 | M13: 28:08:22 | N13: 67%
A14: Magnex | B14: Zona Energy | C14: ENEL 6054 Zona V OPEX SOT SOC-GA | F14: NPY794 | H14: ✔️ | I14: 21171 | J14: 22 | K14: 1042 | L14: 57:40:03 | M14: 14:56:14 | N14: 67%
A15: Magnex | B15: Zona Energy | C15: ENEL 6054 Zona V OPEX SOT SOC-GA | F15: NPY609 | H15: ✔️ | I15: 18011 | J15: 22 | K15: 1337 | L15: 68:47:36 | M15: 32:43:18 | N15: 67%
A16: Magnex | B16: Zona Energy | C16: ENEL 6054 Zona V OPEX SOT SOC-GA | F16: NPY995 | H16: ✔️ | I16: 18436 | J16: 21 | K16: 1167 | L16: 56:30:46 | M16: 23:14:10 | N16: 60%
A17: Magnex | B17: Zona Energy | C17: ENEL 6054 Zona V OPEX SOT SOC-GA | F17: JSL414 | H17: ✔️ | I17: 168484 | J17: 9 | K17: 338 | L17: 14:33:52 | M17: 11:17:12 | N17: 20%
A18: Magnex | B18: Zona Energy | C18: ENEL 6054 Zona V OPEX SOT SOC-GA | F18: GSN681 | H18: ✔️ | I18: 163678 | J18: 20 | K18: 1858 | L18: 75:50:34 | M18: 23:27:37 | N18: 63%
A19: Magnex | B19: Zona Energy | C19: ENEL 6054 Zona V OPEX SOT SOC-GA | F19: NPY976 | H19: ✔️ | I19: 21065 | J19: 19 | K19: 653 | L19: 34:01:42 | M19: 11:30:51 | N19: 47%
... A168: Magnex | B168: Zona Cerrejón | C168: CERREJON 0174 Bombas-GA | F168: NPY487 | H168: ✔️ | I168: 70991 | J168: 3 | K168: 1 | L168: 1:18:14 | M168: 1:39:30 | N168: 0%
A169: Magnex | B169: Zona Drummond | F169: QNN496 | H169: ✔️ | I169: 12755 | J169: 4 | K169: 579 | L169: 23:59:06 | M169: 18:09:37 | N169: 13%
A170: Magnex | B170: Zona Cerrejón | C170: CERREJON 2022 Cabinas-GA | F170: KSR316 | H170: ✔️ | I170: 134942 | J170: 3 | K170: 268 | L170: 9:24:34 | M170: 1:55:24 | N170: 10%
A171: Magnex | B171: Zona Cerrejón | C171: CERREJON 2022 Cabinas-GA | F171: NPY459 | H171: ✔️ | I171: 78104 | J171: 2 | K171: 296 | L171: 10:16:38 | M171: 3:12:50 | N171: 7%
A172: Magnex | B172: Zona Cerrejón | C172: CERREJON 0174 Bombas-GA | F172: LUX622 | H172: ✔️ | I172: 65825 | J172: 3 | K172: 329 | L172: 10:59:09 | M172: 8:59:05 | N172: 10%
A173: Magnex | B173: Zona Cerrejón | C173: CERREJON 2022 Cabinas-GA | F173: KSR314 | H173: ✔️ | I173: 135782 | J173: 1 | K173: 0 | L173: 0:00:04 | M173: 0:00:00 | N173: 0%
A174: Magnex | B174: Zona Cerrejón | C174: CERREJON 3534 Soldadura-GA | F174: KSP722 | H174: ✔️ | I174: 126089 | J174: 0 | K174: 0 | L174: 0:00:00 | M174: 0:00:00 | N174: 0%
A175: Magnex | B175: Zona Cerrejón | C175: CERREJON 0174 Bombas-GA | F175: NPY489 | H175: ✔️ | I175: 67478 | J175: 1 | K175: 0 | L175: 0:10:18 | M175: 0:15:05 | N175: 0%
A176: Magnex | B176: Zona Drummond | C176: DRUMMOND 1547 Liviano-GA | F176: QNN499 | H176: ✔️ | I176: 11621 | J176: 3 | K176: 442 | L176: 19:10:40 | M176: 20:50:53 | N176: 10%
A177: Magnex | B177: Zona Drummond | C177: DRUMMOND 1859T-1885T Mtto - Limpieza-GA | F177: NPY616 | H177: ✔️ | I177: 76972 | J177: 3 | K177: 408 | L177: 14:01:00 | M177: 16:24:54 | N177: 10%
A178: Magnex | B178: Zona Drummond | C178: DRUMMOND 1859T-1885T Mtto - Limpieza-GA | F178: NPY617 | H178: ✔️ | I178: 80424 | J178: 3 | K178: 370 | L178: 17:33:09 | M178: 23:37:48 | N178: 10%
A179: Magnex | B179: Zona Drummond | C179: DRUMMOND 2314 Soldadura-GA | F179: QLO510 | H179: ✔️ | I179: 4511 | J179: 1 | K179: 22 | L179: 0:42:09 | M179: 0:26:00 | N179: 3%
A180: Magnex | B180: Zona Drummond | C180: DRUMMOND 1859T-1885T Mtto - Limpieza-GA | F180: NPY621 | H180: ✔️ | I180: 74944 | J180: 3 | K180: 437 | L180: 25:34:26 | M180: 19:19:47 | N180: 10%
A181: Magnex | B181: Zona Drummond | C181: DRUMMOND 1859T-1885T Mtto - Limpieza-GA | F181: NPY622 | H181: ✔️ | I181: 76078 | J181: 3 | K181: 509 | L181: 24:06:38 | M181: 11:49:22 | N181: 10%
... A198: Magnex | B198: Zona Centro | C198: GMA CENTRO | F198: NPY672 | H198: ✔️ | I198: 69150 | J198: 23 | K198: 2939 | L198: 66:06:58 | M198: 3:33:25 | N198: 77%
A199: Magnex | B199: Zona Energy | C199: ENEL 6234 Zona X OPEX SOT SOC-GA | F199: NPV257 | G199: Jose Yezith Córdoba Leon | H199: ✔️ | I199: 40793 | J199: 20 | K199: 929 | L199: 37:20:59 | M199: 11:15:22 | N199: 57%
A200: Magnex | B200: Zona Cerrejón | C200: CERREJON 2022 Cabinas-GA | F200: NPY484 | H200: ✔️ | I200: 69990 | J200: 27 | K200: 2997 | L200: 88:29:53 | M200: 21:39:09 | N200: 83%
A201: Magnex | B201: Zona Generación | C201: Frontera Energy Col 2679 | F201: QLT551 | H201: ✔️ | I201: 10484 | J201: 30 | K201: 3376 | L201: 165:25:23 | M201: 54:48:15 | N201: 100%
A202: Magnex | B202: Zona Generación | C202: Frontera Energy Col 2679 | F202: QLT553 | H202: ✔️ | I202: 16570 | J202: 30 | K202: 5937 | L202: 290:46:20 | M202: 56:49:21 | N202: 100%
A203: Magnex | B203: Zona Generación | C203: Frontera Energy Col 2679 | F203: PKU060 | H203: ✔️ | I203: 5225 | J203: 30 | K203: 1591 | L203: 106:01:56 | M203: 19:07:04 | N203: 100%
A204: Magnex | B204: Zona Generación | C204: Frontera Energy Col 2679 | F204: QLT576 | H204: ✔️ | I204: 17762 | J204: 30 | K204: 5750 | L204: 316:15:04 | M204: 98:54:41 | N204: 100%
...

Sheet Preinstalado
A1: Grupo 1 | B1: Grupo 2 | C1: Grupo 3 | D1: Grupo 4 | E1: Grupo 5 | F1: Vehículo | G1: Conductor actual | H1: GPS | I1: Odómetro KM | J1: Días conducidos | K1: Kilómetros conducidos | L1: Horas conducidas | M1: Tiempo en ralentí | N1: % de utilización (días conducidos)
A2: Magnex | B2: Asset Information | C2: Powertrain and Fuel Type | D2: Internal Combustion Engine | E2: Diesel | F2: QLO286 | H2: ✔️ | I2: 30820 | J2: 30 | K2: 6044 | L2: 324:19:25 | M2: 66:45:57 | N2: 100%
A3: Magnex | B3: Asset Information | C3: Asset Type | D3: Vehicle | F3: QLO286 | H3: ✔️ | I3: 30820 | J3: 30 | K3: 6044 | L3: 324:19:25 | M3: 66:45:57 | N3: 100%
A4: Magnex | B4: Asset Information | C4: Powertrain and Fuel Type | D4: Internal Combustion Engine | E4: Diesel | F4: NPY686 | H4: ✔️ | I4: 24050 | J4: 22 | K4: 1208 | L4: 42:03:04 | M4: 6:15:20 | N4: 73%
A5: Magnex | B5: Asset Information | C5: Asset Type | D5: Vehicle | F5: NPY686 | H5: ✔️ | I5: 24050 | J5: 22 | K5: 1208 | L5: 42:03:04 | M5: 6:15:20 | N5: 73%
A6: Magnex | B6: Asset Information | C6: Powertrain and Fuel Type | D6: Internal Combustion Engine | E6: Diesel | F6: PMV840 | H6: ✔️ | I6: 7510 | J6: 20 | K6: 483 | L6: 37:13:50 | M6: 16:04:40 | N6: 63%
A7: Magnex | B7: Asset Information | C7: Asset Type | D7: Vehicle | F7: PMV840 | H7: ✔️ | I7: 7510 | J7: 20 | K7: 483 | L7: 37:13:50 | M7: 16:04:40 | N7: 63%
A8: Magnex | B8: Asset Information | C8: Powertrain and Fuel Type | D8: Internal Combustion Engine | E8: Diesel | F8: NPY798 | H8: ✔️ | I8: 10809 | J8: 26 | K8: 860 | L8: 66:33:51 | M8: 26:01:28 | N8: 83%
A9: Magnex | B9: Asset Information | C9: Asset Type | D9: Vehicle | F9: NPY798 | H9: ✔️ | I9: 10809 | J9: 26 | K9: 860 | L9: 66:33:51 | M9: 26:01:28 | N9: 83%
A10: Magnex | B10: Asset Information | C10: Powertrain and Fuel Type | D10: Internal Combustion Engine | E10: Diesel | F10: GSO698 | H10: ✔️ | I10: 138492 | J10: 24 | K10: 3187 | L10: 131:38:31 | M10: 39:19:25 | N10: 80%
A11: Magnex | B11: Asset Information | C11: Powertrain and Fuel Type | D11: Manually Classified Powertrain | F11: GSO698 | H11: ✔️ | I11: 138492 | J11: 24 | K11: 3187 | L11: 131:38:31 | M11: 39:19:25 | N11: 80%
A12: Magnex | B12: Asset Information | C12: Asset Type | D12: Vehicle | F12: GSO698 | H12: ✔️ | I12: 138492 | J12: 24 | K12: 3187 | L12: 131:38:31 | M12: 39:19:25 | N12: 80%
A13: Magnex | B13: Asset Information | C13: Powertrain and Fuel Type | D13: Internal Combustion Engine | E13: Diesel | F13: NPY979 | H13: ✔️ | I13: 20833 | J13: 20 | K13: 1701 | L13: 72:58:59 | M13: 28:08:22 | N13: 67%
A14: Magnex | B14: Asset Information | C14: Asset Type | D14: Vehicle | F14: NPY979 | H14: ✔️ | I14: 20833 | J14: 20 | K14: 1701 | L14: 72:58:59 | M14: 28:08:22 | N14: 67%
A15: Magnex | B15: Asset Information | C15: Powertrain and Fuel Type | D15: Internal Combustion Engine | E15: Diesel | F15: NPY794 | H15: ✔️ | I15: 21171 | J15: 22 | K15: 1042 | L15: 57:40:03 | M15: 14:56:14 | N15: 67%
A16: Magnex | B16: Asset Information | C16: Asset Type | D16: Vehicle | F16: NPY794 | H16: ✔️ | I16: 21171 | J16: 22 | K16: 1042 | L16: 57:40:03 | M16: 14:56:14 | N16: 67%
A17: Magnex | B17: Asset Information | C17: Powertrain and Fuel Type | D17: Internal Combustion Engine | E17: Diesel | F17: NPY609 | H17: ✔️ | I17: 18011 | J17: 22 | K17: 1337 | L17: 68:47:36 | M17: 32:43:18 | N17: 67%
A18: Magnex | B18: Asset Information | C18: Asset Type | D18: Vehicle | F18: NPY609 | H18: ✔️ | I18: 18011 | J18: 22 | K18: 1337 | L18: 68:47:36 | M18: 32:43:18 | N18: 67%
A19: Magnex | B19: Asset Information | C19: Powertrain and Fuel Type | D19: Internal Combustion Engine | E19: Diesel | F19: NPY995 | H19: ✔️ | I19: 18436 | J19: 21 | K19: 1167 | L19: 56:30:46 | M19: 23:14:10 | N19: 60%
A20: Magnex | B20: Asset Information | C20: Asset Type | D20: Vehicle | F20: NPY995 | H20: ✔️ | I20: 18436 | J20: 21 | K20: 1167 | L20: 56:30:46 | M20: 23:14:10 | N20: 60%
A21: Magnex | B21: Asset Information | C21: Powertrain and Fuel Type | D21: Internal Combustion Engine | E21: Diesel | F21: JSL414 | H21: ✔️ | I21: 168484 | J21: 9 | K21: 338 | L21: 14:33:52 | M21: 11:17:12 | N21: 20%
A22: Magnex | B22: Asset Information | C22: Asset Type | D22: Vehicle | F22: JSL414 | H22: ✔️ | I22: 168484 | J22: 9 | K22: 338 | L22: 14:33:52 | M22: 11:17:12 | N22: 20%
A23: Magnex | B23: Asset Information | C23: Powertrain and Fuel Type | D23: Internal Combustion Engine | E23: Diesel | F23: GSN681 | H23: ✔️ | I23: 163678 | J23: 20 | K23: 1858 | L23: 75:50:34 | M23: 23:27:37 | N23: 63%
A24: Magnex | B24: Asset Information | C24: Powertrain and Fuel Type | D24: Manually Classified Powertrain | F24: GSN681 | H24: ✔️ | I24: 163678 | J24: 20 | K24: 1858 | L24: 75:50:34 | M24: 23:27:37 | N24: 63%
A25: Magnex | B25: Asset Information | C25: Asset Type | D25: Vehicle | F25: GSN681 | H25: ✔️ | I25: 163678 | J25: 20 | K25: 1858 | L25: 75:50:34 | M25: 23:27:37 | N25: 63%
A26: Magnex | B26: Asset Information | C26: Powertrain and Fuel Type | D26: Internal Combustion Engine | E26: Diesel | F26: NPY976 | H26: ✔️ | I26: 21065 | J26: 19 | K26: 653 | L26: 34:01:42 | M26: 11:30:51 | N26: 47%
A27: Magnex | B27: Asset Information | C27: Asset Type | D27: Vehicle | F27: NPY976 | H27: ✔️ | I27: 21065 | J27: 19 | K27: 653 | L27: 34:01:42 | M27: 11:30:51 | N27: 47%
A28: Magnex | B28: Asset Information | C28: Powertrain and Fuel Type | D28: Internal Combustion Engine | E28: Diesel | F28: NPY986 | H28: ✔️ | I28: 15024 | J28: 18 | K28: 712 | L28: 34:11:37 | M28: 15:33:28 | N28: 50%
